# 补充

- 断言
- traceback 的使用
- logging 的时候如何写异常处理，实际情况中如何使用。

# 异常

异常：

- 异常是 Python 对象，表示一个错误。


异常的处理：

- 当 Python 脚本发生异常时我们需要捕获处理它，否则程序会终止执行。


## 标准异常种类

| 异常名称                  | 描述                                               |
| ------------------------- | -------------------------------------------------- |
| BaseException             | 所有异常的基类                                     |
| SystemExit                | 解释器请求退出                                     |
| KeyboardInterrupt         | 用户中断执行(通常是输入^C)                         |
| Exception                 | 常规错误的基类                                     |
| StopIteration             | 迭代器没有更多的值                                 |
| GeneratorExit             | 生成器(generator)发生异常来通知退出                |
| StandardError             | 所有的内建标准异常的基类                           |
| ArithmeticError           | 所有数值计算错误的基类                             |
| FloatingPointError        | 浮点计算错误                                       |
| OverflowError             | 数值运算超出最大限制                               |
| ZeroDivisionError         | 除(或取模)零 (所有数据类型)                        |
| AssertionError            | 断言语句失败                                       |
| AttributeError            | 对象没有这个属性                                   |
| EOFError                  | 没有内建输入，到达 EOF 标记                        |
| EnvironmentError          | 操作系统错误的基类                                 |
| IOError                   | 输入/输出操作失败                                  |
| OSError                   | 操作系统错误                                       |
| WindowsError              | 系统调用失败                                       |
| ImportError               | 导入模块/对象失败                                  |
| LookupError               | 无效数据查询的基类                                 |
| IndexError                | 序列中没有此索引(index)                            |
| KeyError                  | 映射中没有这个键                                   |
| MemoryError               | 内存溢出错误(对于 Python 解释器不是致命的)         |
| NameError                 | 未声明/初始化对象 (没有属性)                       |
| UnboundLocalError         | 访问未初始化的本地变量                             |
| ReferenceError            | 弱引用(Weak reference)试图访问已经垃圾回收了的对象 |
| RuntimeError              | 一般的运行时错误                                   |
| NotImplementedError       | 尚未实现的方法                                     |
| SyntaxError               | Python 语法错误                                    |
| IndentationError          | 缩进错误                                           |
| TabError                  | Tab 和空格混用                                     |
| SystemError               | 一般的解释器系统错误                               |
| TypeError                 | 对类型无效的操作                                   |
| ValueError                | 传入无效的参数                                     |
| UnicodeError              | Unicode 相关的错误                                 |
| UnicodeDecodeError        | Unicode 解码时的错误                               |
| UnicodeEncodeError        | Unicode 编码时错误                                 |
| UnicodeTranslateError     | Unicode 转换时错误                                 |
| Warning                   | 警告的基类                                         |
| DeprecationWarning        | 关于被弃用的特征的警告                             |
| FutureWarning             | 关于构造将来语义会有改变的警告                     |
| OverflowWarning           | 旧的关于自动提升为长整型(long)的警告               |
| PendingDeprecationWarning | 关于特性将会被废弃的警告                           |
| RuntimeWarning            | 可疑的运行时行为(runtime behavior)的警告           |
| SyntaxWarning             | 可疑的语法的警告                                   |
| UserWarning               | 用户代码生成的警告                                 |




## 处理异常 `try except else finally`


**举例1：**


下面是简单的例子，它打开一个文件，在该文件中的内容写入内容，且并未发生异常：


```python
try:
   fh = open("testfile", "w")
   fh.write("This is my test file for exception handling!!")
except IOError:
   print "Error: can\'t find file or read data"
else:
   print "Written content in the file successfully"
   fh.close()
```

输出：


```
Written content in the file successfully
```



**举例 2：**

介绍：

- 它打开一个文件，在该文件中的内容写入内容，但文件没有写入权限，发生了异常。


```python
try:
   fh = open("testfile", "w")
   fh.write("This is my test file for exception handling!!")
except IOError:
   print "Error: can\'t find file or read data"
else:
   print "Written content in the file successfully"
```

输出：

```
Error: can't find file or read data
```


**举例 3：**


```py
f = open(path, 'w')
try:
    write_to_file(f)
except:
    print('Failed')
else:
    print('Succeeded')
finally:
    f.close()
```

说明：

- else 可以让 try 里的代码成功执行后，让 `print('Succeeded')` 执行。
- finally 会始终会让 f 关闭。



## 异常作为参数 Argument


异常作为参数传递出来：

举例：

```py
def temp_convert(var):
    try:
        return int(var)
    except ValueError as Argument:
        print("The argument does not contain numbers\n", Argument)

temp_convert("xyz");
```

输出：

```txt
The argument does not contain numbers
 invalid literal for int() with base 10: 'xyz'
```

说明：

- 变量接收的异常值通常包含在异常的语句中。在元组的表单中变量可以接收一个或者多个值。
- 元组通常包含错误字符串，错误数字，错误位置。


# 引发异常 `raise`

举例：

```py
def my_abs(x):
    if not isinstance(x, (int, float)):
        raise TypeError('bad operand type')
    if x >= 0:
        return x
    else:
        return -x

try:
    my_abs('A')
except Exception as Arg:
    print(Arg)

print('---')

my_abs('A')
```

输出：

```
bad operand type
---
Traceback (most recent call last):
  File "D:/21.Practice/demo/t.py", line 17, in <module>
    my_abs('A')
  File "D:/21.Practice/demo/t.py", line 3, in my_abs
    raise TypeError('bad operand type')
TypeError: bad operand type
```

注意：

- 写程序要严密，当出现异常的情况的时候，该抛出来就要抛出来，想办法来解决这个异常，而不是藏着掖着，装作没看见，装作不知道。


## 用户自定义异常

（后续补充）

举例：

```py
class Networkerror(RuntimeError):
    def __init__(self, arg):
        self.args = arg

try:
    raise Networkerror("Bad hostname")
except Networkerror as e:
    print(type(e.args))
    print(e.args)
```


输出：

```
<class 'tuple'>
('B', 'a', 'd', ' ', 'h', 'o', 's', 't', 'n', 'a', 'm', 'e')
```

不清楚的：

- 为什么会输出一个 tuple？而且，内容是这个？


## 规范异常输出格式

（补充关于 traceback）

举例：

```python
import traceback

print('########################################################')
print("1/0 Exception Info")
print('---------------------------------------------------------')
try:
    1 / 0
except Exception as e:
    print('str(Exception):\t', str(Exception))
    print('str(e):\t\t', str(e))
    print('repr(e):\t', repr(e))
    print('traceback.format_exc():\n%s' % traceback.format_exc())
print('########################################################')
print('\n########################################################')
print("i = int('a') Exception Info")
print('---------------------------------------------------------')
try:
    i = int('a')
except Exception as e:
    print('str(Exception):\t', str(Exception))
    print('str(e):\t\t', str(e))
    print('repr(e):\t', repr(e))
    print('traceback.format_exc():\n%s' % traceback.format_exc())
print('########################################################')

```

输出：

```
########################################################
1/0 Exception Info
---------------------------------------------------------
str(Exception):	 <class 'Exception'>
str(e):		 division by zero
repr(e):	 ZeroDivisionError('division by zero')
traceback.format_exc():
Traceback (most recent call last):
  File "D:/21.Practice/demo/d.py", line 7, in <module>
    1 / 0
ZeroDivisionError: division by zero

########################################################

########################################################
i = int('a') Exception Info
---------------------------------------------------------
str(Exception):	 <class 'Exception'>
str(e):		 invalid literal for int() with base 10: 'a'
repr(e):	 ValueError("invalid literal for int() with base 10: 'a'")
traceback.format_exc():
Traceback (most recent call last):
  File "D:/21.Practice/demo/d.py", line 18, in <module>
    i = int('a')
ValueError: invalid literal for int() with base 10: 'a'

########################################################
```

