# 异常

## 捕获异常 try except else finally 

举例：

```py
try:
    print('try')
    r = 10 / int('0')
    print('result:', r)
except ValueError as e:
    print('ValueError:', e)
except UnicodeError as e:
    print('UnicodeError')
except ZeroDivisionError as e:
    print('ZeroDivisionError:', e)
else:
    print('no error!')
finally:
    print('finally')
print('END')
```

输出：

```txt
try
ZeroDivisionError: division by zero
finally
END
```

说明：

- 当我们认为某些代码可能会出错时，就可以用`try`来运行这段代码，如果执行出错，则后续代码不会继续执行，而是直接跳转至错误处理代码，即 `except` 语句块。
- 执行完 `except` 后，如果有 `finally` 语句块，则执行 `finally` 语句块。
- 从输出可以看到，当错误发生时，后续语句`print('result:', r)`不会被执行。
- 注意：所有的异常类型都继承自 `BaseException`，所以在使用 `except` 时需要注意：它不但捕获该类型的错误，还把其子类也“一网打尽”。
  - 比如：`UnicodeError` 永远也捕获不到，因为 `UnicodeError` 是 `ValueError` 的子类，如果有，也被第一个 `except` 给捕获了。


应用：

- 使用`try...except`捕获错误还有一个巨大的好处，就是可以跨越多层调用。

```py
def foo(s):
    return 10 / int(s)

def bar(s):
    return foo(s) * 2

def main():
    try:
        bar('0')
    except Exception as e:
        print('Error:', e)
    finally:
        print('finally...')
```

说明：

- 函数`main()`调用`foo()`，`foo()`调用`bar()`，结果`bar()`出错了，这时，只要`main()`捕获到了，就可以处理，不需要在每个可能出错的地方去捕获错误，只要在合适的层次去捕获错误就可以了。这样一来，就大大减少了写 `try...except...finally` 的麻烦。

## 异常的错误信息堆栈

- 如果错误没有被捕获，它就会一直往上抛，最后被 Python 解释器捕获，打印一个错误信息，然后程序退出。

举例：

```py
def foo(s):
    return 10 / int(s)

def bar(s):
    return foo(s) * 2

def main():
    bar('0')

main()
```

执行，结果如下：

```txt
Traceback (most recent call last):
  File "D:/21.Practice/demo/t.py", line 10, in <module>
    main()
  File "D:/21.Practice/demo/t.py", line 8, in main
    bar('0')
  File "D:/21.Practice/demo/t.py", line 5, in bar
    return foo(s) * 2
  File "D:/21.Practice/demo/t.py", line 2, in foo
    return 10 / int(s)
ZeroDivisionError: division by zero
```

说明：

- `Traceback (most recent call last)` 告诉我们这是错误的跟踪信息。
- `File "D:/21.Practice/demo/t.py", line 10, in <module> main()` 第10 行调用 main 时候错了。
- 根据错误类型`ZeroDivisionError`，我们判断，`int(s)`本身并没有出错，但是`int(s)`返回`0`，在计算`10 / 0`时出错，至此，找到错误源头。


## 记录错误信息堆栈 logging

（补充，这里没写怎么配置。）

```py
import logging

def foo(s):
    return 10 / int(s)

def bar(s):
    return foo(s) * 2

def main():
    try:
        bar('0')
    except Exception as e:
        logging.exception(e)

main()
print('END')
```

输出：

```txt
ERROR:root:division by zero
Traceback (most recent call last):
  File "D:/21.Practice/demo/t.py", line 11, in main
    bar('0')
  File "D:/21.Practice/demo/t.py", line 7, in bar
    return foo(s) * 2
  File "D:/21.Practice/demo/t.py", line 4, in foo
    return 10 / int(s)
ZeroDivisionError: division by zero
END
```

## 抛出错误 raise

**举例1：**

```py
class FooError(ValueError):
    pass

def foo(s):
    n = int(s)
    if n==0:
        raise FooError('invalid value: %s' % s)
    return 10 / n

foo('0')
```

输出：

```py
Traceback (most recent call last):
  File "D:/21.Practice/demo/t.py", line 10, in <module>
    foo('0')
  File "D:/21.Practice/demo/t.py", line 7, in foo
    raise FooError('invalid value: %s' % s)
__main__.FooError: invalid value: 0
```

说明：

- 只有在必要的时候才定义我们自己的错误类型。如果可以选择 Python 已有的内置的错误类型（比如`ValueError`，`TypeError`），尽量使用 Python 内置的错误类型。

**举例2：**

```py
# err_reraise.py

def foo(s):
    n = int(s)
    if n==0:
        raise ValueError('invalid value: %s' % s)
    return 10 / n

def bar():
    try:
        foo('0')
    except ValueError as e:
        print('ValueError!')
        raise

bar()
```

说明：

- 为什么，在`bar()`函数中，明明已经捕获了错误，但是，打印一个`ValueError!`后，又把错误通过`raise`语句抛出去了？
  - 这种处理比较常见。捕获错误目的只是记录一下，便于后续追踪。但是，由于当前函数不知道应该怎么处理该错误，所以，最恰当的方式是继续往上抛，让顶层调用者去处理。
- `raise`语句如果不带参数，就会把当前错误原样抛出。


## 标准异常种类

| 异常名称                  | 描述                                               |
| ------------------------- | -------------------------------------------------- |
| BaseException             | 所有异常的基类                                     |
| SystemExit                | 解释器请求退出                                     |
| KeyboardInterrupt         | 用户中断执行(通常是输入^C)                         |
| Exception                 | 常规错误的基类                                     |
| StopIteration             | 迭代器没有更多的值                                 |
| GeneratorExit             | 生成器(generator)发生异常来通知退出                |
| StandardError             | 所有的内建标准异常的基类                           |
| ArithmeticError           | 所有数值计算错误的基类                             |
| FloatingPointError        | 浮点计算错误                                       |
| OverflowError             | 数值运算超出最大限制                               |
| ZeroDivisionError         | 除(或取模)零 (所有数据类型)                        |
| AssertionError            | 断言语句失败                                       |
| AttributeError            | 对象没有这个属性                                   |
| EOFError                  | 没有内建输入，到达 EOF 标记                        |
| EnvironmentError          | 操作系统错误的基类                                 |
| IOError                   | 输入/输出操作失败                                  |
| OSError                   | 操作系统错误                                       |
| WindowsError              | 系统调用失败                                       |
| ImportError               | 导入模块/对象失败                                  |
| LookupError               | 无效数据查询的基类                                 |
| IndexError                | 序列中没有此索引(index)                            |
| KeyError                  | 映射中没有这个键                                   |
| MemoryError               | 内存溢出错误(对于 Python 解释器不是致命的)         |
| NameError                 | 未声明/初始化对象 (没有属性)                       |
| UnboundLocalError         | 访问未初始化的本地变量                             |
| ReferenceError            | 弱引用(Weak reference)试图访问已经垃圾回收了的对象 |
| RuntimeError              | 一般的运行时错误                                   |
| NotImplementedError       | 尚未实现的方法                                     |
| SyntaxError               | Python 语法错误                                    |
| IndentationError          | 缩进错误                                           |
| TabError                  | Tab 和空格混用                                     |
| SystemError               | 一般的解释器系统错误                               |
| TypeError                 | 对类型无效的操作                                   |
| ValueError                | 传入无效的参数                                     |
| UnicodeError              | Unicode 相关的错误                                 |
| UnicodeDecodeError        | Unicode 解码时的错误                               |
| UnicodeEncodeError        | Unicode 编码时错误                                 |
| UnicodeTranslateError     | Unicode 转换时错误                                 |
| Warning                   | 警告的基类                                         |
| DeprecationWarning        | 关于被弃用的特征的警告                             |
| FutureWarning             | 关于构造将来语义会有改变的警告                     |
| OverflowWarning           | 旧的关于自动提升为长整型(long)的警告               |
| PendingDeprecationWarning | 关于特性将会被废弃的警告                           |
| RuntimeWarning            | 可疑的运行时行为(runtime behavior)的警告           |
| SyntaxWarning             | 可疑的语法的警告                                   |
| UserWarning               | 用户代码生成的警告                                 |




## 异常的继承关系

```txt
BaseException
 +-- SystemExit
 +-- KeyboardInterrupt
 +-- GeneratorExit
 +-- Exception
      +-- StopIteration
      +-- StopAsyncIteration
      +-- ArithmeticError
      |    +-- FloatingPointError
      |    +-- OverflowError
      |    +-- ZeroDivisionError
      +-- AssertionError
      +-- AttributeError
      +-- BufferError
      +-- EOFError
      +-- ImportError
      |    +-- ModuleNotFoundError
      +-- LookupError
      |    +-- IndexError
      |    +-- KeyError
      +-- MemoryError
      +-- NameError
      |    +-- UnboundLocalError
      +-- OSError
      |    +-- BlockingIOError
      |    +-- ChildProcessError
      |    +-- ConnectionError
      |    |    +-- BrokenPipeError
      |    |    +-- ConnectionAbortedError
      |    |    +-- ConnectionRefusedError
      |    |    +-- ConnectionResetError
      |    +-- FileExistsError
      |    +-- FileNotFoundError
      |    +-- InterruptedError
      |    +-- IsADirectoryError
      |    +-- NotADirectoryError
      |    +-- PermissionError
      |    +-- ProcessLookupError
      |    +-- TimeoutError
      +-- ReferenceError
      +-- RuntimeError
      |    +-- NotImplementedError
      |    +-- RecursionError
      +-- SyntaxError
      |    +-- IndentationError
      |         +-- TabError
      +-- SystemError
      +-- TypeError
      +-- ValueError
      |    +-- UnicodeError
      |         +-- UnicodeDecodeError
      |         +-- UnicodeEncodeError
      |         +-- UnicodeTranslateError
      +-- Warning
           +-- DeprecationWarning
           +-- PendingDeprecationWarning
           +-- RuntimeWarning
           +-- SyntaxWarning
           +-- UserWarning
           +-- FutureWarning
           +-- ImportWarning
           +-- UnicodeWarning
           +-- BytesWarning
           +-- ResourceWarning
```

